[2023-10-26T07:07:28.519+0000] {taskinstance.py:1157} INFO - Dependencies all met for dep_context=non-requeueable deps ti=<TaskInstance: etl_dag.load_data manual__2023-10-26T07:02:00.120485+00:00 [queued]>
[2023-10-26T07:07:28.596+0000] {taskinstance.py:1157} INFO - Dependencies all met for dep_context=requeueable deps ti=<TaskInstance: etl_dag.load_data manual__2023-10-26T07:02:00.120485+00:00 [queued]>
[2023-10-26T07:07:28.599+0000] {taskinstance.py:1359} INFO - Starting attempt 2 of 3
[2023-10-26T07:07:28.641+0000] {taskinstance.py:1380} INFO - Executing <Task(PythonOperator): load_data> on 2023-10-26 07:02:00.120485+00:00
[2023-10-26T07:07:28.667+0000] {standard_task_runner.py:57} INFO - Started process 73 to run task
[2023-10-26T07:07:28.672+0000] {standard_task_runner.py:84} INFO - Running: ['***', 'tasks', 'run', 'etl_dag', 'load_data', 'manual__2023-10-26T07:02:00.120485+00:00', '--job-id', '457', '--raw', '--subdir', 'DAGS_FOLDER/tugaskel8_dag.py', '--cfg-path', '/tmp/tmpgycsx2ov']
[2023-10-26T07:07:28.688+0000] {standard_task_runner.py:85} INFO - Job 457: Subtask load_data
[2023-10-26T07:07:29.514+0000] {task_command.py:415} INFO - Running <TaskInstance: etl_dag.load_data manual__2023-10-26T07:02:00.120485+00:00 [running]> on host d73c1ff20372
[2023-10-26T07:07:30.768+0000] {taskinstance.py:1660} INFO - Exporting env vars: AIRFLOW_CTX_DAG_OWNER='kel8' AIRFLOW_CTX_DAG_ID='etl_dag' AIRFLOW_CTX_TASK_ID='load_data' AIRFLOW_CTX_EXECUTION_DATE='2023-10-26T07:02:00.120485+00:00' AIRFLOW_CTX_TRY_NUMBER='2' AIRFLOW_CTX_DAG_RUN_ID='manual__2023-10-26T07:02:00.120485+00:00'
[2023-10-26T07:07:31.164+0000] {base.py:73} INFO - Using connection ID 'db_polusiudara' for task execution.
[2023-10-26T07:07:36.867+0000] {python.py:194} INFO - Done. Returned value was: Sukses Memasukkan Data
[2023-10-26T07:07:45.480+0000] {job.py:219} ERROR - Job heartbeat got an exception
Traceback (most recent call last):
  File "/home/airflow/.local/lib/python3.8/site-packages/sqlalchemy/engine/base.py", line 3371, in _wrap_pool_connect
    return fn()
  File "/home/airflow/.local/lib/python3.8/site-packages/sqlalchemy/pool/base.py", line 327, in connect
    return _ConnectionFairy._checkout(self)
  File "/home/airflow/.local/lib/python3.8/site-packages/sqlalchemy/pool/base.py", line 894, in _checkout
    fairy = _ConnectionRecord.checkout(pool)
  File "/home/airflow/.local/lib/python3.8/site-packages/sqlalchemy/pool/base.py", line 493, in checkout
    rec = pool._do_get()
  File "/home/airflow/.local/lib/python3.8/site-packages/sqlalchemy/pool/impl.py", line 256, in _do_get
    return self._create_connection()
  File "/home/airflow/.local/lib/python3.8/site-packages/sqlalchemy/pool/base.py", line 273, in _create_connection
    return _ConnectionRecord(self)
  File "/home/airflow/.local/lib/python3.8/site-packages/sqlalchemy/pool/base.py", line 388, in __init__
    self.__connect()
  File "/home/airflow/.local/lib/python3.8/site-packages/sqlalchemy/pool/base.py", line 691, in __connect
    pool.logger.debug("Error on connect(): %s", e)
  File "/home/airflow/.local/lib/python3.8/site-packages/sqlalchemy/util/langhelpers.py", line 70, in __exit__
    compat.raise_(
  File "/home/airflow/.local/lib/python3.8/site-packages/sqlalchemy/util/compat.py", line 211, in raise_
    raise exception
  File "/home/airflow/.local/lib/python3.8/site-packages/sqlalchemy/pool/base.py", line 686, in __connect
    self.dbapi_connection = connection = pool._invoke_creator(self)
  File "/home/airflow/.local/lib/python3.8/site-packages/sqlalchemy/engine/create.py", line 574, in connect
    return dialect.connect(*cargs, **cparams)
  File "/home/airflow/.local/lib/python3.8/site-packages/sqlalchemy/engine/default.py", line 598, in connect
    return self.dbapi.connect(*cargs, **cparams)
  File "/home/airflow/.local/lib/python3.8/site-packages/psycopg2/__init__.py", line 122, in connect
    conn = _connect(dsn, connection_factory=connection_factory, **kwasync)
psycopg2.OperationalError: could not translate host name "postgres" to address: Temporary failure in name resolution


The above exception was the direct cause of the following exception:

Traceback (most recent call last):
  File "/home/airflow/.local/lib/python3.8/site-packages/airflow/jobs/job.py", line 190, in heartbeat
    session.merge(self)
  File "/home/airflow/.local/lib/python3.8/site-packages/sqlalchemy/orm/session.py", line 3056, in merge
    return self._merge(
  File "/home/airflow/.local/lib/python3.8/site-packages/sqlalchemy/orm/session.py", line 3136, in _merge
    merged = self.get(
  File "/home/airflow/.local/lib/python3.8/site-packages/sqlalchemy/orm/session.py", line 2853, in get
    return self._get_impl(
  File "/home/airflow/.local/lib/python3.8/site-packages/sqlalchemy/orm/session.py", line 2975, in _get_impl
    return db_load_fn(
  File "/home/airflow/.local/lib/python3.8/site-packages/sqlalchemy/orm/loading.py", line 530, in load_on_pk_identity
    session.execute(
  File "/home/airflow/.local/lib/python3.8/site-packages/sqlalchemy/orm/session.py", line 1716, in execute
    conn = self._connection_for_bind(bind)
  File "/home/airflow/.local/lib/python3.8/site-packages/sqlalchemy/orm/session.py", line 1555, in _connection_for_bind
    return self._transaction._connection_for_bind(
  File "/home/airflow/.local/lib/python3.8/site-packages/sqlalchemy/orm/session.py", line 750, in _connection_for_bind
    conn = bind.connect()
  File "/home/airflow/.local/lib/python3.8/site-packages/sqlalchemy/future/engine.py", line 406, in connect
    return super(Engine, self).connect()
  File "/home/airflow/.local/lib/python3.8/site-packages/sqlalchemy/engine/base.py", line 3325, in connect
    return self._connection_cls(self, close_with_result=close_with_result)
  File "/home/airflow/.local/lib/python3.8/site-packages/sqlalchemy/engine/base.py", line 96, in __init__
    else engine.raw_connection()
  File "/home/airflow/.local/lib/python3.8/site-packages/sqlalchemy/engine/base.py", line 3404, in raw_connection
    return self._wrap_pool_connect(self.pool.connect, _connection)
  File "/home/airflow/.local/lib/python3.8/site-packages/sqlalchemy/engine/base.py", line 3374, in _wrap_pool_connect
    Connection._handle_dbapi_exception_noconnection(
  File "/home/airflow/.local/lib/python3.8/site-packages/sqlalchemy/engine/base.py", line 2208, in _handle_dbapi_exception_noconnection
    util.raise_(
  File "/home/airflow/.local/lib/python3.8/site-packages/sqlalchemy/util/compat.py", line 211, in raise_
    raise exception
  File "/home/airflow/.local/lib/python3.8/site-packages/sqlalchemy/engine/base.py", line 3371, in _wrap_pool_connect
    return fn()
  File "/home/airflow/.local/lib/python3.8/site-packages/sqlalchemy/pool/base.py", line 327, in connect
    return _ConnectionFairy._checkout(self)
  File "/home/airflow/.local/lib/python3.8/site-packages/sqlalchemy/pool/base.py", line 894, in _checkout
    fairy = _ConnectionRecord.checkout(pool)
  File "/home/airflow/.local/lib/python3.8/site-packages/sqlalchemy/pool/base.py", line 493, in checkout
    rec = pool._do_get()
  File "/home/airflow/.local/lib/python3.8/site-packages/sqlalchemy/pool/impl.py", line 256, in _do_get
    return self._create_connection()
  File "/home/airflow/.local/lib/python3.8/site-packages/sqlalchemy/pool/base.py", line 273, in _create_connection
    return _ConnectionRecord(self)
  File "/home/airflow/.local/lib/python3.8/site-packages/sqlalchemy/pool/base.py", line 388, in __init__
    self.__connect()
  File "/home/airflow/.local/lib/python3.8/site-packages/sqlalchemy/pool/base.py", line 691, in __connect
    pool.logger.debug("Error on connect(): %s", e)
  File "/home/airflow/.local/lib/python3.8/site-packages/sqlalchemy/util/langhelpers.py", line 70, in __exit__
    compat.raise_(
  File "/home/airflow/.local/lib/python3.8/site-packages/sqlalchemy/util/compat.py", line 211, in raise_
    raise exception
  File "/home/airflow/.local/lib/python3.8/site-packages/sqlalchemy/pool/base.py", line 686, in __connect
    self.dbapi_connection = connection = pool._invoke_creator(self)
  File "/home/airflow/.local/lib/python3.8/site-packages/sqlalchemy/engine/create.py", line 574, in connect
    return dialect.connect(*cargs, **cparams)
  File "/home/airflow/.local/lib/python3.8/site-packages/sqlalchemy/engine/default.py", line 598, in connect
    return self.dbapi.connect(*cargs, **cparams)
  File "/home/airflow/.local/lib/python3.8/site-packages/psycopg2/__init__.py", line 122, in connect
    conn = _connect(dsn, connection_factory=connection_factory, **kwasync)
sqlalchemy.exc.OperationalError: (psycopg2.OperationalError) could not translate host name "postgres" to address: Temporary failure in name resolution

(Background on this error at: https://sqlalche.me/e/14/e3q8)
[2023-10-26T07:07:46.925+0000] {taskinstance.py:1935} ERROR - Task failed with exception
Traceback (most recent call last):
  File "/home/airflow/.local/lib/python3.8/site-packages/sqlalchemy/engine/base.py", line 3371, in _wrap_pool_connect
    return fn()
  File "/home/airflow/.local/lib/python3.8/site-packages/sqlalchemy/pool/base.py", line 327, in connect
    return _ConnectionFairy._checkout(self)
  File "/home/airflow/.local/lib/python3.8/site-packages/sqlalchemy/pool/base.py", line 894, in _checkout
    fairy = _ConnectionRecord.checkout(pool)
  File "/home/airflow/.local/lib/python3.8/site-packages/sqlalchemy/pool/base.py", line 493, in checkout
    rec = pool._do_get()
  File "/home/airflow/.local/lib/python3.8/site-packages/sqlalchemy/pool/impl.py", line 256, in _do_get
    return self._create_connection()
  File "/home/airflow/.local/lib/python3.8/site-packages/sqlalchemy/pool/base.py", line 273, in _create_connection
    return _ConnectionRecord(self)
  File "/home/airflow/.local/lib/python3.8/site-packages/sqlalchemy/pool/base.py", line 388, in __init__
    self.__connect()
  File "/home/airflow/.local/lib/python3.8/site-packages/sqlalchemy/pool/base.py", line 691, in __connect
    pool.logger.debug("Error on connect(): %s", e)
  File "/home/airflow/.local/lib/python3.8/site-packages/sqlalchemy/util/langhelpers.py", line 70, in __exit__
    compat.raise_(
  File "/home/airflow/.local/lib/python3.8/site-packages/sqlalchemy/util/compat.py", line 211, in raise_
    raise exception
  File "/home/airflow/.local/lib/python3.8/site-packages/sqlalchemy/pool/base.py", line 686, in __connect
    self.dbapi_connection = connection = pool._invoke_creator(self)
  File "/home/airflow/.local/lib/python3.8/site-packages/sqlalchemy/engine/create.py", line 574, in connect
    return dialect.connect(*cargs, **cparams)
  File "/home/airflow/.local/lib/python3.8/site-packages/sqlalchemy/engine/default.py", line 598, in connect
    return self.dbapi.connect(*cargs, **cparams)
  File "/home/airflow/.local/lib/python3.8/site-packages/psycopg2/__init__.py", line 122, in connect
    conn = _connect(dsn, connection_factory=connection_factory, **kwasync)
psycopg2.OperationalError: could not translate host name "postgres" to address: Temporary failure in name resolution


The above exception was the direct cause of the following exception:

Traceback (most recent call last):
  File "/home/airflow/.local/lib/python3.8/site-packages/airflow/utils/session.py", line 74, in wrapper
    return func(*args, **kwargs)
  File "/home/airflow/.local/lib/python3.8/site-packages/airflow/models/taskinstance.py", line 2477, in xcom_push
    XCom.set(
  File "/home/airflow/.local/lib/python3.8/site-packages/airflow/utils/session.py", line 74, in wrapper
    return func(*args, **kwargs)
  File "/home/airflow/.local/lib/python3.8/site-packages/airflow/models/xcom.py", line 219, in set
    dag_run_id = session.query(DagRun.id).filter_by(dag_id=dag_id, run_id=run_id).scalar()
  File "/home/airflow/.local/lib/python3.8/site-packages/sqlalchemy/orm/query.py", line 2893, in scalar
    ret = self.one()
  File "/home/airflow/.local/lib/python3.8/site-packages/sqlalchemy/orm/query.py", line 2870, in one
    return self._iter().one()
  File "/home/airflow/.local/lib/python3.8/site-packages/sqlalchemy/orm/query.py", line 2916, in _iter
    result = self.session.execute(
  File "/home/airflow/.local/lib/python3.8/site-packages/sqlalchemy/orm/session.py", line 1716, in execute
    conn = self._connection_for_bind(bind)
  File "/home/airflow/.local/lib/python3.8/site-packages/sqlalchemy/orm/session.py", line 1555, in _connection_for_bind
    return self._transaction._connection_for_bind(
  File "/home/airflow/.local/lib/python3.8/site-packages/sqlalchemy/orm/session.py", line 750, in _connection_for_bind
    conn = bind.connect()
  File "/home/airflow/.local/lib/python3.8/site-packages/sqlalchemy/future/engine.py", line 406, in connect
    return super(Engine, self).connect()
  File "/home/airflow/.local/lib/python3.8/site-packages/sqlalchemy/engine/base.py", line 3325, in connect
    return self._connection_cls(self, close_with_result=close_with_result)
  File "/home/airflow/.local/lib/python3.8/site-packages/sqlalchemy/engine/base.py", line 96, in __init__
    else engine.raw_connection()
  File "/home/airflow/.local/lib/python3.8/site-packages/sqlalchemy/engine/base.py", line 3404, in raw_connection
    return self._wrap_pool_connect(self.pool.connect, _connection)
  File "/home/airflow/.local/lib/python3.8/site-packages/sqlalchemy/engine/base.py", line 3374, in _wrap_pool_connect
    Connection._handle_dbapi_exception_noconnection(
  File "/home/airflow/.local/lib/python3.8/site-packages/sqlalchemy/engine/base.py", line 2208, in _handle_dbapi_exception_noconnection
    util.raise_(
  File "/home/airflow/.local/lib/python3.8/site-packages/sqlalchemy/util/compat.py", line 211, in raise_
    raise exception
  File "/home/airflow/.local/lib/python3.8/site-packages/sqlalchemy/engine/base.py", line 3371, in _wrap_pool_connect
    return fn()
  File "/home/airflow/.local/lib/python3.8/site-packages/sqlalchemy/pool/base.py", line 327, in connect
    return _ConnectionFairy._checkout(self)
  File "/home/airflow/.local/lib/python3.8/site-packages/sqlalchemy/pool/base.py", line 894, in _checkout
    fairy = _ConnectionRecord.checkout(pool)
  File "/home/airflow/.local/lib/python3.8/site-packages/sqlalchemy/pool/base.py", line 493, in checkout
    rec = pool._do_get()
  File "/home/airflow/.local/lib/python3.8/site-packages/sqlalchemy/pool/impl.py", line 256, in _do_get
    return self._create_connection()
  File "/home/airflow/.local/lib/python3.8/site-packages/sqlalchemy/pool/base.py", line 273, in _create_connection
    return _ConnectionRecord(self)
  File "/home/airflow/.local/lib/python3.8/site-packages/sqlalchemy/pool/base.py", line 388, in __init__
    self.__connect()
  File "/home/airflow/.local/lib/python3.8/site-packages/sqlalchemy/pool/base.py", line 691, in __connect
    pool.logger.debug("Error on connect(): %s", e)
  File "/home/airflow/.local/lib/python3.8/site-packages/sqlalchemy/util/langhelpers.py", line 70, in __exit__
    compat.raise_(
  File "/home/airflow/.local/lib/python3.8/site-packages/sqlalchemy/util/compat.py", line 211, in raise_
    raise exception
  File "/home/airflow/.local/lib/python3.8/site-packages/sqlalchemy/pool/base.py", line 686, in __connect
    self.dbapi_connection = connection = pool._invoke_creator(self)
  File "/home/airflow/.local/lib/python3.8/site-packages/sqlalchemy/engine/create.py", line 574, in connect
    return dialect.connect(*cargs, **cparams)
  File "/home/airflow/.local/lib/python3.8/site-packages/sqlalchemy/engine/default.py", line 598, in connect
    return self.dbapi.connect(*cargs, **cparams)
  File "/home/airflow/.local/lib/python3.8/site-packages/psycopg2/__init__.py", line 122, in connect
    conn = _connect(dsn, connection_factory=connection_factory, **kwasync)
sqlalchemy.exc.OperationalError: (psycopg2.OperationalError) could not translate host name "postgres" to address: Temporary failure in name resolution

(Background on this error at: https://sqlalche.me/e/14/e3q8)
[2023-10-26T07:07:53.786+0000] {taskinstance.py:1398} INFO - Marking task as UP_FOR_RETRY. dag_id=etl_dag, task_id=load_data, execution_date=20231026T070200, start_date=20231026T070728, end_date=20231026T070753
[2023-10-26T07:07:53.871+0000] {standard_task_runner.py:104} ERROR - Failed to execute job 457 for task load_data ((psycopg2.OperationalError) could not translate host name "postgres" to address: Temporary failure in name resolution

(Background on this error at: https://sqlalche.me/e/14/e3q8); 73)
[2023-10-26T07:07:53.924+0000] {local_task_job_runner.py:228} INFO - Task exited with return code 1
[2023-10-26T07:07:54.013+0000] {taskinstance.py:2776} INFO - 0 downstream tasks scheduled from follow-on schedule check
