[2023-10-24T15:55:27.144+0000] {taskinstance.py:1157} INFO - Dependencies all met for dep_context=non-requeueable deps ti=<TaskInstance: etl_dag.transform_data manual__2023-10-24T15:54:59.239250+00:00 [queued]>
[2023-10-24T15:55:27.158+0000] {taskinstance.py:1157} INFO - Dependencies all met for dep_context=requeueable deps ti=<TaskInstance: etl_dag.transform_data manual__2023-10-24T15:54:59.239250+00:00 [queued]>
[2023-10-24T15:55:27.160+0000] {taskinstance.py:1359} INFO - Starting attempt 1 of 3
[2023-10-24T15:55:27.603+0000] {taskinstance.py:1380} INFO - Executing <Task(PythonOperator): transform_data> on 2023-10-24 15:54:59.239250+00:00
[2023-10-24T15:55:29.281+0000] {standard_task_runner.py:57} INFO - Started process 1099 to run task
[2023-10-24T15:55:32.470+0000] {standard_task_runner.py:84} INFO - Running: ['***', 'tasks', 'run', 'etl_dag', 'transform_data', 'manual__2023-10-24T15:54:59.239250+00:00', '--job-id', '79', '--raw', '--subdir', 'DAGS_FOLDER/tugaskel8_dag.py', '--cfg-path', '/tmp/tmpm_x6li0f']
[2023-10-24T15:55:32.517+0000] {standard_task_runner.py:85} INFO - Job 79: Subtask transform_data
[2023-10-24T15:55:32.940+0000] {task_command.py:415} INFO - Running <TaskInstance: etl_dag.transform_data manual__2023-10-24T15:54:59.239250+00:00 [running]> on host 5628b0258ab1
[2023-10-24T15:55:33.603+0000] {taskinstance.py:1660} INFO - Exporting env vars: AIRFLOW_CTX_DAG_OWNER='kel8' AIRFLOW_CTX_DAG_ID='etl_dag' AIRFLOW_CTX_TASK_ID='transform_data' AIRFLOW_CTX_EXECUTION_DATE='2023-10-24T15:54:59.239250+00:00' AIRFLOW_CTX_TRY_NUMBER='1' AIRFLOW_CTX_DAG_RUN_ID='manual__2023-10-24T15:54:59.239250+00:00'
[2023-10-24T15:55:33.714+0000] {taskinstance.py:1935} ERROR - Task failed with exception
Traceback (most recent call last):
  File "/home/airflow/.local/lib/python3.8/site-packages/airflow/operators/python.py", line 192, in execute
    return_value = self.execute_callable()
  File "/home/airflow/.local/lib/python3.8/site-packages/airflow/operators/python.py", line 209, in execute_callable
    return self.python_callable(*self.op_args, **self.op_kwargs)
  File "/opt/airflow/dags/tugaskel8_dag.py", line 33, in transform_data
    tes_data = response.json(data)
NameError: name 'response' is not defined
[2023-10-24T15:55:33.817+0000] {taskinstance.py:1398} INFO - Marking task as UP_FOR_RETRY. dag_id=etl_dag, task_id=transform_data, execution_date=20231024T155459, start_date=20231024T155527, end_date=20231024T155533
[2023-10-24T15:55:33.852+0000] {standard_task_runner.py:104} ERROR - Failed to execute job 79 for task transform_data (name 'response' is not defined; 1099)
[2023-10-24T15:55:33.897+0000] {local_task_job_runner.py:228} INFO - Task exited with return code 1
[2023-10-24T15:55:33.942+0000] {taskinstance.py:2776} INFO - 0 downstream tasks scheduled from follow-on schedule check
