[2023-10-24T15:56:24.099+0000] {taskinstance.py:1157} INFO - Dependencies all met for dep_context=non-requeueable deps ti=<TaskInstance: etl_dag.transform_data scheduled__2023-10-24T15:50:45.028545+00:00 [queued]>
[2023-10-24T15:56:24.117+0000] {taskinstance.py:1157} INFO - Dependencies all met for dep_context=requeueable deps ti=<TaskInstance: etl_dag.transform_data scheduled__2023-10-24T15:50:45.028545+00:00 [queued]>
[2023-10-24T15:56:24.118+0000] {taskinstance.py:1359} INFO - Starting attempt 2 of 3
[2023-10-24T15:56:24.143+0000] {taskinstance.py:1380} INFO - Executing <Task(PythonOperator): transform_data> on 2023-10-24 15:50:45.028545+00:00
[2023-10-24T15:56:24.156+0000] {standard_task_runner.py:57} INFO - Started process 1124 to run task
[2023-10-24T15:56:24.162+0000] {standard_task_runner.py:84} INFO - Running: ['***', 'tasks', 'run', 'etl_dag', 'transform_data', 'scheduled__2023-10-24T15:50:45.028545+00:00', '--job-id', '82', '--raw', '--subdir', 'DAGS_FOLDER/tugaskel8_dag.py', '--cfg-path', '/tmp/tmpk3rv_i0c']
[2023-10-24T15:56:24.166+0000] {standard_task_runner.py:85} INFO - Job 82: Subtask transform_data
[2023-10-24T15:56:24.249+0000] {task_command.py:415} INFO - Running <TaskInstance: etl_dag.transform_data scheduled__2023-10-24T15:50:45.028545+00:00 [running]> on host 5628b0258ab1
[2023-10-24T15:56:24.419+0000] {taskinstance.py:1660} INFO - Exporting env vars: AIRFLOW_CTX_DAG_OWNER='kel8' AIRFLOW_CTX_DAG_ID='etl_dag' AIRFLOW_CTX_TASK_ID='transform_data' AIRFLOW_CTX_EXECUTION_DATE='2023-10-24T15:50:45.028545+00:00' AIRFLOW_CTX_TRY_NUMBER='2' AIRFLOW_CTX_DAG_RUN_ID='scheduled__2023-10-24T15:50:45.028545+00:00'
[2023-10-24T15:56:24.450+0000] {taskinstance.py:1935} ERROR - Task failed with exception
Traceback (most recent call last):
  File "/home/airflow/.local/lib/python3.8/site-packages/airflow/operators/python.py", line 192, in execute
    return_value = self.execute_callable()
  File "/home/airflow/.local/lib/python3.8/site-packages/airflow/operators/python.py", line 209, in execute_callable
    return self.python_callable(*self.op_args, **self.op_kwargs)
  File "/opt/airflow/dags/tugaskel8_dag.py", line 33, in transform_data
    tes_data = response.json(data)
NameError: name 'response' is not defined
[2023-10-24T15:56:24.474+0000] {taskinstance.py:1398} INFO - Marking task as UP_FOR_RETRY. dag_id=etl_dag, task_id=transform_data, execution_date=20231024T155045, start_date=20231024T155624, end_date=20231024T155624
[2023-10-24T15:56:24.496+0000] {standard_task_runner.py:104} ERROR - Failed to execute job 82 for task transform_data (name 'response' is not defined; 1124)
[2023-10-24T15:56:24.535+0000] {local_task_job_runner.py:228} INFO - Task exited with return code 1
[2023-10-24T15:56:24.779+0000] {taskinstance.py:2776} INFO - 0 downstream tasks scheduled from follow-on schedule check
