[2023-10-26T06:03:23.455+0000] {taskinstance.py:1157} INFO - Dependencies all met for dep_context=non-requeueable deps ti=<TaskInstance: etl_dag.load_data manual__2023-10-26T05:43:09.884996+00:00 [queued]>
[2023-10-26T06:03:23.510+0000] {taskinstance.py:1157} INFO - Dependencies all met for dep_context=requeueable deps ti=<TaskInstance: etl_dag.load_data manual__2023-10-26T05:43:09.884996+00:00 [queued]>
[2023-10-26T06:03:23.512+0000] {taskinstance.py:1359} INFO - Starting attempt 3 of 3
[2023-10-26T06:03:23.567+0000] {taskinstance.py:1380} INFO - Executing <Task(PythonOperator): load_data> on 2023-10-26 05:43:09.884996+00:00
[2023-10-26T06:03:23.588+0000] {standard_task_runner.py:57} INFO - Started process 1863 to run task
[2023-10-26T06:03:23.588+0000] {standard_task_runner.py:84} INFO - Running: ['***', 'tasks', 'run', 'etl_dag', 'load_data', 'manual__2023-10-26T05:43:09.884996+00:00', '--job-id', '368', '--raw', '--subdir', 'DAGS_FOLDER/tugaskel8_dag.py', '--cfg-path', '/tmp/tmpjt5ja4ad']
[2023-10-26T06:03:23.596+0000] {standard_task_runner.py:85} INFO - Job 368: Subtask load_data
[2023-10-26T06:03:23.683+0000] {task_command.py:415} INFO - Running <TaskInstance: etl_dag.load_data manual__2023-10-26T05:43:09.884996+00:00 [running]> on host d73c1ff20372
[2023-10-26T06:03:25.938+0000] {taskinstance.py:1660} INFO - Exporting env vars: AIRFLOW_CTX_DAG_OWNER='kel8' AIRFLOW_CTX_DAG_ID='etl_dag' AIRFLOW_CTX_TASK_ID='load_data' AIRFLOW_CTX_EXECUTION_DATE='2023-10-26T05:43:09.884996+00:00' AIRFLOW_CTX_TRY_NUMBER='3' AIRFLOW_CTX_DAG_RUN_ID='manual__2023-10-26T05:43:09.884996+00:00'
[2023-10-26T06:03:26.844+0000] {base.py:73} INFO - Using connection ID 'db_polusiudara' for task execution.
[2023-10-26T06:03:27.017+0000] {taskinstance.py:1935} ERROR - Task failed with exception
Traceback (most recent call last):
  File "/home/airflow/.local/lib/python3.8/site-packages/airflow/operators/python.py", line 192, in execute
    return_value = self.execute_callable()
  File "/home/airflow/.local/lib/python3.8/site-packages/airflow/operators/python.py", line 209, in execute_callable
    return self.python_callable(*self.op_args, **self.op_kwargs)
  File "/opt/airflow/dags/tugaskel8_dag.py", line 55, in load_data
    hook.run(f"INSERT INTO hands_on_final (id,city,name,entity,country,sources,isMobile,isAnalysis,sensorType,firstUpdated,lastUpdated,measurements) VALUES ({row['id']}, {row['city']}, '{row['name']}', '{row['entity']}', '{row['country']}', '{row['sources']}', {row['isMobile']}, {row['isAnalysis']}, '{row['sensorType']}', '{row['firstUpdated']}', '{row['lastUpdated']}', {row['measurements']})")
  File "/home/airflow/.local/lib/python3.8/site-packages/airflow/providers/common/sql/hooks/sql.py", line 385, in run
    with closing(self.get_conn()) as conn:
  File "/home/airflow/.local/lib/python3.8/site-packages/airflow/providers/postgres/hooks/postgres.py", line 154, in get_conn
    self.conn = psycopg2.connect(**conn_args)
  File "/home/airflow/.local/lib/python3.8/site-packages/psycopg2/__init__.py", line 122, in connect
    conn = _connect(dsn, connection_factory=connection_factory, **kwasync)
psycopg2.OperationalError: could not translate host name "ep-rough-sun-65050822.ap-southeast-1.aws.neon.tech" to address: Name or service not known

[2023-10-26T06:03:27.044+0000] {taskinstance.py:1398} INFO - Marking task as FAILED. dag_id=etl_dag, task_id=load_data, execution_date=20231026T054309, start_date=20231026T060323, end_date=20231026T060327
[2023-10-26T06:03:27.072+0000] {standard_task_runner.py:104} ERROR - Failed to execute job 368 for task load_data (could not translate host name "ep-rough-sun-65050822.ap-southeast-1.aws.neon.tech" to address: Name or service not known
; 1863)
[2023-10-26T06:03:27.126+0000] {local_task_job_runner.py:228} INFO - Task exited with return code 1
[2023-10-26T06:03:27.150+0000] {taskinstance.py:2776} INFO - 0 downstream tasks scheduled from follow-on schedule check
