[2023-10-24T17:15:24.978+0000] {taskinstance.py:1157} INFO - Dependencies all met for dep_context=non-requeueable deps ti=<TaskInstance: etl_dag.transform_data manual__2023-10-24T17:05:01.022003+00:00 [queued]>
[2023-10-24T17:15:24.994+0000] {taskinstance.py:1157} INFO - Dependencies all met for dep_context=requeueable deps ti=<TaskInstance: etl_dag.transform_data manual__2023-10-24T17:05:01.022003+00:00 [queued]>
[2023-10-24T17:15:24.995+0000] {taskinstance.py:1359} INFO - Starting attempt 3 of 3
[2023-10-24T17:15:25.014+0000] {taskinstance.py:1380} INFO - Executing <Task(PythonOperator): transform_data> on 2023-10-24 17:05:01.022003+00:00
[2023-10-24T17:15:25.052+0000] {standard_task_runner.py:57} INFO - Started process 397 to run task
[2023-10-24T17:15:25.055+0000] {standard_task_runner.py:84} INFO - Running: ['***', 'tasks', 'run', 'etl_dag', 'transform_data', 'manual__2023-10-24T17:05:01.022003+00:00', '--job-id', '132', '--raw', '--subdir', 'DAGS_FOLDER/tugaskel8_dag.py', '--cfg-path', '/tmp/tmpr5jmcehc']
[2023-10-24T17:15:25.059+0000] {standard_task_runner.py:85} INFO - Job 132: Subtask transform_data
[2023-10-24T17:15:25.132+0000] {task_command.py:415} INFO - Running <TaskInstance: etl_dag.transform_data manual__2023-10-24T17:05:01.022003+00:00 [running]> on host d73c1ff20372
[2023-10-24T17:15:25.485+0000] {taskinstance.py:1660} INFO - Exporting env vars: AIRFLOW_CTX_DAG_OWNER='kel8' AIRFLOW_CTX_DAG_ID='etl_dag' AIRFLOW_CTX_TASK_ID='transform_data' AIRFLOW_CTX_EXECUTION_DATE='2023-10-24T17:05:01.022003+00:00' AIRFLOW_CTX_TRY_NUMBER='3' AIRFLOW_CTX_DAG_RUN_ID='manual__2023-10-24T17:05:01.022003+00:00'
[2023-10-24T17:15:25.501+0000] {taskinstance.py:1935} ERROR - Task failed with exception
Traceback (most recent call last):
  File "/home/airflow/.local/lib/python3.8/site-packages/airflow/operators/python.py", line 192, in execute
    return_value = self.execute_callable()
  File "/home/airflow/.local/lib/python3.8/site-packages/airflow/operators/python.py", line 209, in execute_callable
    return self.python_callable(*self.op_args, **self.op_kwargs)
  File "/opt/airflow/dags/tugaskel8_dag.py", line 34, in transform_data
    results = tes_data['results']
KeyError: 'results'
[2023-10-24T17:15:25.523+0000] {taskinstance.py:1398} INFO - Marking task as FAILED. dag_id=etl_dag, task_id=transform_data, execution_date=20231024T170501, start_date=20231024T171524, end_date=20231024T171525
[2023-10-24T17:15:25.540+0000] {standard_task_runner.py:104} ERROR - Failed to execute job 132 for task transform_data ('results'; 397)
[2023-10-24T17:15:25.592+0000] {local_task_job_runner.py:228} INFO - Task exited with return code 1
[2023-10-24T17:15:25.622+0000] {taskinstance.py:2776} INFO - 0 downstream tasks scheduled from follow-on schedule check
