[2023-10-26T06:43:12.944+0000] {taskinstance.py:1157} INFO - Dependencies all met for dep_context=non-requeueable deps ti=<TaskInstance: etl_dag.load_data manual__2023-10-26T06:42:57.672174+00:00 [queued]>
[2023-10-26T06:43:12.958+0000] {taskinstance.py:1157} INFO - Dependencies all met for dep_context=requeueable deps ti=<TaskInstance: etl_dag.load_data manual__2023-10-26T06:42:57.672174+00:00 [queued]>
[2023-10-26T06:43:12.959+0000] {taskinstance.py:1359} INFO - Starting attempt 1 of 3
[2023-10-26T06:43:12.977+0000] {taskinstance.py:1380} INFO - Executing <Task(PythonOperator): load_data> on 2023-10-26 06:42:57.672174+00:00
[2023-10-26T06:43:12.987+0000] {standard_task_runner.py:57} INFO - Started process 2762 to run task
[2023-10-26T06:43:12.991+0000] {standard_task_runner.py:84} INFO - Running: ['***', 'tasks', 'run', 'etl_dag', 'load_data', 'manual__2023-10-26T06:42:57.672174+00:00', '--job-id', '401', '--raw', '--subdir', 'DAGS_FOLDER/tugaskel8_dag.py', '--cfg-path', '/tmp/tmpj6zm9u8i']
[2023-10-26T06:43:12.995+0000] {standard_task_runner.py:85} INFO - Job 401: Subtask load_data
[2023-10-26T06:43:13.068+0000] {task_command.py:415} INFO - Running <TaskInstance: etl_dag.load_data manual__2023-10-26T06:42:57.672174+00:00 [running]> on host d73c1ff20372
[2023-10-26T06:43:13.472+0000] {taskinstance.py:1660} INFO - Exporting env vars: AIRFLOW_CTX_DAG_OWNER='kel8' AIRFLOW_CTX_DAG_ID='etl_dag' AIRFLOW_CTX_TASK_ID='load_data' AIRFLOW_CTX_EXECUTION_DATE='2023-10-26T06:42:57.672174+00:00' AIRFLOW_CTX_TRY_NUMBER='1' AIRFLOW_CTX_DAG_RUN_ID='manual__2023-10-26T06:42:57.672174+00:00'
[2023-10-26T06:43:13.812+0000] {base.py:73} INFO - Using connection ID 'db_polusiudara' for task execution.
[2023-10-26T06:43:13.813+0000] {taskinstance.py:1935} ERROR - Task failed with exception
Traceback (most recent call last):
  File "/home/airflow/.local/lib/python3.8/site-packages/airflow/operators/python.py", line 192, in execute
    return_value = self.execute_callable()
  File "/home/airflow/.local/lib/python3.8/site-packages/airflow/operators/python.py", line 209, in execute_callable
    return self.python_callable(*self.op_args, **self.op_kwargs)
  File "/opt/airflow/dags/tugaskel8_dag.py", line 59, in load_data
    final_df.to_sql('hands_on_final',hook.get_sqlalchemy_engine(),if_exists='append',index=False,dtype={"parameters": hook.types.JSON,"coordinates" :hook.types.JSON,"bounds" : hook.types.JSON,"manufacturers":hook.types.JSON  })
AttributeError: 'PostgresHook' object has no attribute 'types'
[2023-10-26T06:43:13.835+0000] {taskinstance.py:1398} INFO - Marking task as UP_FOR_RETRY. dag_id=etl_dag, task_id=load_data, execution_date=20231026T064257, start_date=20231026T064312, end_date=20231026T064313
[2023-10-26T06:43:13.864+0000] {standard_task_runner.py:104} ERROR - Failed to execute job 401 for task load_data ('PostgresHook' object has no attribute 'types'; 2762)
[2023-10-26T06:43:13.927+0000] {local_task_job_runner.py:228} INFO - Task exited with return code 1
[2023-10-26T06:43:13.955+0000] {taskinstance.py:2776} INFO - 0 downstream tasks scheduled from follow-on schedule check
