[2023-10-26T04:29:08.434+0000] {taskinstance.py:1157} INFO - Dependencies all met for dep_context=non-requeueable deps ti=<TaskInstance: etl_dag.load_data manual__2023-10-26T04:23:55.474420+00:00 [queued]>
[2023-10-26T04:29:08.452+0000] {taskinstance.py:1157} INFO - Dependencies all met for dep_context=requeueable deps ti=<TaskInstance: etl_dag.load_data manual__2023-10-26T04:23:55.474420+00:00 [queued]>
[2023-10-26T04:29:08.453+0000] {taskinstance.py:1359} INFO - Starting attempt 2 of 3
[2023-10-26T04:29:08.473+0000] {taskinstance.py:1380} INFO - Executing <Task(PythonOperator): load_data> on 2023-10-26 04:23:55.474420+00:00
[2023-10-26T04:29:08.482+0000] {standard_task_runner.py:57} INFO - Started process 1086 to run task
[2023-10-26T04:29:08.485+0000] {standard_task_runner.py:84} INFO - Running: ['***', 'tasks', 'run', 'etl_dag', 'load_data', 'manual__2023-10-26T04:23:55.474420+00:00', '--job-id', '207', '--raw', '--subdir', 'DAGS_FOLDER/tugaskel8_dag.py', '--cfg-path', '/tmp/tmprofmbt4i']
[2023-10-26T04:29:08.488+0000] {standard_task_runner.py:85} INFO - Job 207: Subtask load_data
[2023-10-26T04:29:08.639+0000] {task_command.py:415} INFO - Running <TaskInstance: etl_dag.load_data manual__2023-10-26T04:23:55.474420+00:00 [running]> on host d73c1ff20372
[2023-10-26T04:29:08.989+0000] {taskinstance.py:1660} INFO - Exporting env vars: AIRFLOW_CTX_DAG_OWNER='kel8' AIRFLOW_CTX_DAG_ID='etl_dag' AIRFLOW_CTX_TASK_ID='load_data' AIRFLOW_CTX_EXECUTION_DATE='2023-10-26T04:23:55.474420+00:00' AIRFLOW_CTX_TRY_NUMBER='2' AIRFLOW_CTX_DAG_RUN_ID='manual__2023-10-26T04:23:55.474420+00:00'
[2023-10-26T04:29:09.021+0000] {base.py:73} INFO - Using connection ID 'db_polusiudara' for task execution.
[2023-10-26T04:29:09.883+0000] {taskinstance.py:1935} ERROR - Task failed with exception
Traceback (most recent call last):
  File "/home/airflow/.local/lib/python3.8/site-packages/airflow/operators/python.py", line 192, in execute
    return_value = self.execute_callable()
  File "/home/airflow/.local/lib/python3.8/site-packages/airflow/operators/python.py", line 209, in execute_callable
    return self.python_callable(*self.op_args, **self.op_kwargs)
  File "/opt/airflow/dags/tugaskel8_dag.py", line 47, in load_data
    final_df.to_sql('hands_on_final',hook.get_sqlalchemy_engine(),if_exists='replace')
AttributeError: 'list' object has no attribute 'to_sql'
[2023-10-26T04:29:09.902+0000] {taskinstance.py:1398} INFO - Marking task as UP_FOR_RETRY. dag_id=etl_dag, task_id=load_data, execution_date=20231026T042355, start_date=20231026T042908, end_date=20231026T042909
[2023-10-26T04:29:09.922+0000] {standard_task_runner.py:104} ERROR - Failed to execute job 207 for task load_data ('list' object has no attribute 'to_sql'; 1086)
[2023-10-26T04:29:09.944+0000] {local_task_job_runner.py:228} INFO - Task exited with return code 1
[2023-10-26T04:29:09.967+0000] {taskinstance.py:2776} INFO - 0 downstream tasks scheduled from follow-on schedule check
