[2023-10-26T04:47:47.499+0000] {taskinstance.py:1157} INFO - Dependencies all met for dep_context=non-requeueable deps ti=<TaskInstance: etl_dag.load_data manual__2023-10-26T04:42:36.466865+00:00 [queued]>
[2023-10-26T04:47:47.519+0000] {taskinstance.py:1157} INFO - Dependencies all met for dep_context=requeueable deps ti=<TaskInstance: etl_dag.load_data manual__2023-10-26T04:42:36.466865+00:00 [queued]>
[2023-10-26T04:47:47.519+0000] {taskinstance.py:1359} INFO - Starting attempt 2 of 3
[2023-10-26T04:47:47.535+0000] {taskinstance.py:1380} INFO - Executing <Task(PythonOperator): load_data> on 2023-10-26 04:42:36.466865+00:00
[2023-10-26T04:47:47.543+0000] {standard_task_runner.py:57} INFO - Started process 1607 to run task
[2023-10-26T04:47:47.547+0000] {standard_task_runner.py:84} INFO - Running: ['***', 'tasks', 'run', 'etl_dag', 'load_data', 'manual__2023-10-26T04:42:36.466865+00:00', '--job-id', '238', '--raw', '--subdir', 'DAGS_FOLDER/tugaskel8_dag.py', '--cfg-path', '/tmp/tmpdsf9g4rx']
[2023-10-26T04:47:47.550+0000] {standard_task_runner.py:85} INFO - Job 238: Subtask load_data
[2023-10-26T04:47:47.608+0000] {task_command.py:415} INFO - Running <TaskInstance: etl_dag.load_data manual__2023-10-26T04:42:36.466865+00:00 [running]> on host d73c1ff20372
[2023-10-26T04:47:47.897+0000] {taskinstance.py:1660} INFO - Exporting env vars: AIRFLOW_CTX_DAG_OWNER='kel8' AIRFLOW_CTX_DAG_ID='etl_dag' AIRFLOW_CTX_TASK_ID='load_data' AIRFLOW_CTX_EXECUTION_DATE='2023-10-26T04:42:36.466865+00:00' AIRFLOW_CTX_TRY_NUMBER='2' AIRFLOW_CTX_DAG_RUN_ID='manual__2023-10-26T04:42:36.466865+00:00'
[2023-10-26T04:47:48.090+0000] {taskinstance.py:1935} ERROR - Task failed with exception
Traceback (most recent call last):
  File "/home/airflow/.local/lib/python3.8/site-packages/airflow/operators/python.py", line 192, in execute
    return_value = self.execute_callable()
  File "/home/airflow/.local/lib/python3.8/site-packages/airflow/operators/python.py", line 209, in execute_callable
    return self.python_callable(*self.op_args, **self.op_kwargs)
  File "/opt/airflow/dags/tugaskel8_dag.py", line 45, in load_data
    final_df['coordinates'] = final_df['coordinates'].apply(lambda x: json.loads(x))
  File "/home/airflow/.local/lib/python3.8/site-packages/pandas/core/series.py", line 4630, in apply
    return SeriesApply(self, func, convert_dtype, args, kwargs).apply()
  File "/home/airflow/.local/lib/python3.8/site-packages/pandas/core/apply.py", line 1025, in apply
    return self.apply_standard()
  File "/home/airflow/.local/lib/python3.8/site-packages/pandas/core/apply.py", line 1076, in apply_standard
    mapped = lib.map_infer(
  File "pandas/_libs/lib.pyx", line 2834, in pandas._libs.lib.map_infer
  File "/opt/airflow/dags/tugaskel8_dag.py", line 45, in <lambda>
    final_df['coordinates'] = final_df['coordinates'].apply(lambda x: json.loads(x))
  File "/usr/local/lib/python3.8/json/__init__.py", line 341, in loads
    raise TypeError(f'the JSON object must be str, bytes or bytearray, '
TypeError: the JSON object must be str, bytes or bytearray, not dict
[2023-10-26T04:47:48.114+0000] {taskinstance.py:1398} INFO - Marking task as UP_FOR_RETRY. dag_id=etl_dag, task_id=load_data, execution_date=20231026T044236, start_date=20231026T044747, end_date=20231026T044748
[2023-10-26T04:47:48.132+0000] {standard_task_runner.py:104} ERROR - Failed to execute job 238 for task load_data (the JSON object must be str, bytes or bytearray, not dict; 1607)
[2023-10-26T04:47:48.162+0000] {local_task_job_runner.py:228} INFO - Task exited with return code 1
[2023-10-26T04:47:48.184+0000] {taskinstance.py:2776} INFO - 0 downstream tasks scheduled from follow-on schedule check
