[2023-10-24T15:47:40.769+0000] {taskinstance.py:1157} INFO - Dependencies all met for dep_context=non-requeueable deps ti=<TaskInstance: etl_dag.transform_data scheduled__2023-10-24T15:47:06.078597+00:00 [queued]>
[2023-10-24T15:47:40.783+0000] {taskinstance.py:1157} INFO - Dependencies all met for dep_context=requeueable deps ti=<TaskInstance: etl_dag.transform_data scheduled__2023-10-24T15:47:06.078597+00:00 [queued]>
[2023-10-24T15:47:40.784+0000] {taskinstance.py:1359} INFO - Starting attempt 1 of 3
[2023-10-24T15:47:40.809+0000] {taskinstance.py:1380} INFO - Executing <Task(PythonOperator): transform_data> on 2023-10-24 15:47:06.078597+00:00
[2023-10-24T15:47:40.816+0000] {standard_task_runner.py:57} INFO - Started process 853 to run task
[2023-10-24T15:47:40.822+0000] {standard_task_runner.py:84} INFO - Running: ['***', 'tasks', 'run', 'etl_dag', 'transform_data', 'scheduled__2023-10-24T15:47:06.078597+00:00', '--job-id', '35', '--raw', '--subdir', 'DAGS_FOLDER/tugaskel8_dag.py', '--cfg-path', '/tmp/tmpgtq71bf5']
[2023-10-24T15:47:40.825+0000] {standard_task_runner.py:85} INFO - Job 35: Subtask transform_data
[2023-10-24T15:47:40.884+0000] {task_command.py:415} INFO - Running <TaskInstance: etl_dag.transform_data scheduled__2023-10-24T15:47:06.078597+00:00 [running]> on host 5628b0258ab1
[2023-10-24T15:47:40.984+0000] {taskinstance.py:1660} INFO - Exporting env vars: AIRFLOW_CTX_DAG_OWNER='kel8' AIRFLOW_CTX_DAG_ID='etl_dag' AIRFLOW_CTX_TASK_ID='transform_data' AIRFLOW_CTX_EXECUTION_DATE='2023-10-24T15:47:06.078597+00:00' AIRFLOW_CTX_TRY_NUMBER='1' AIRFLOW_CTX_DAG_RUN_ID='scheduled__2023-10-24T15:47:06.078597+00:00'
[2023-10-24T15:47:41.004+0000] {taskinstance.py:1935} ERROR - Task failed with exception
Traceback (most recent call last):
  File "/home/airflow/.local/lib/python3.8/site-packages/airflow/operators/python.py", line 192, in execute
    return_value = self.execute_callable()
  File "/home/airflow/.local/lib/python3.8/site-packages/airflow/operators/python.py", line 209, in execute_callable
    return self.python_callable(*self.op_args, **self.op_kwargs)
  File "/opt/airflow/dags/tugaskel8_dag.py", line 33, in transform_data
    tes_data = data['results']
TypeError: string indices must be integers
[2023-10-24T15:47:41.023+0000] {taskinstance.py:1398} INFO - Marking task as UP_FOR_RETRY. dag_id=etl_dag, task_id=transform_data, execution_date=20231024T154706, start_date=20231024T154740, end_date=20231024T154741
[2023-10-24T15:47:41.039+0000] {standard_task_runner.py:104} ERROR - Failed to execute job 35 for task transform_data (string indices must be integers; 853)
[2023-10-24T15:47:41.074+0000] {local_task_job_runner.py:228} INFO - Task exited with return code 1
[2023-10-24T15:47:41.095+0000] {taskinstance.py:2776} INFO - 0 downstream tasks scheduled from follow-on schedule check
