[2023-10-26T05:34:16.094+0000] {taskinstance.py:1157} INFO - Dependencies all met for dep_context=non-requeueable deps ti=<TaskInstance: etl_dag.load_data manual__2023-10-26T05:24:00.630684+00:00 [queued]>
[2023-10-26T05:34:16.108+0000] {taskinstance.py:1157} INFO - Dependencies all met for dep_context=requeueable deps ti=<TaskInstance: etl_dag.load_data manual__2023-10-26T05:24:00.630684+00:00 [queued]>
[2023-10-26T05:34:16.109+0000] {taskinstance.py:1359} INFO - Starting attempt 3 of 3
[2023-10-26T05:34:16.126+0000] {taskinstance.py:1380} INFO - Executing <Task(PythonOperator): load_data> on 2023-10-26 05:24:00.630684+00:00
[2023-10-26T05:34:16.135+0000] {standard_task_runner.py:57} INFO - Started process 1368 to run task
[2023-10-26T05:34:16.139+0000] {standard_task_runner.py:84} INFO - Running: ['***', 'tasks', 'run', 'etl_dag', 'load_data', 'manual__2023-10-26T05:24:00.630684+00:00', '--job-id', '346', '--raw', '--subdir', 'DAGS_FOLDER/tugaskel8_dag.py', '--cfg-path', '/tmp/tmpun23_xrl']
[2023-10-26T05:34:16.143+0000] {standard_task_runner.py:85} INFO - Job 346: Subtask load_data
[2023-10-26T05:34:16.198+0000] {task_command.py:415} INFO - Running <TaskInstance: etl_dag.load_data manual__2023-10-26T05:24:00.630684+00:00 [running]> on host d73c1ff20372
[2023-10-26T05:34:16.465+0000] {taskinstance.py:1660} INFO - Exporting env vars: AIRFLOW_CTX_DAG_OWNER='kel8' AIRFLOW_CTX_DAG_ID='etl_dag' AIRFLOW_CTX_TASK_ID='load_data' AIRFLOW_CTX_EXECUTION_DATE='2023-10-26T05:24:00.630684+00:00' AIRFLOW_CTX_TRY_NUMBER='3' AIRFLOW_CTX_DAG_RUN_ID='manual__2023-10-26T05:24:00.630684+00:00'
[2023-10-26T05:34:16.521+0000] {taskinstance.py:1935} ERROR - Task failed with exception
Traceback (most recent call last):
  File "/home/airflow/.local/lib/python3.8/site-packages/pandas/core/indexes/base.py", line 3653, in get_loc
    return self._engine.get_loc(casted_key)
  File "pandas/_libs/index.pyx", line 147, in pandas._libs.index.IndexEngine.get_loc
  File "pandas/_libs/index.pyx", line 176, in pandas._libs.index.IndexEngine.get_loc
  File "pandas/_libs/hashtable_class_helper.pxi", line 7080, in pandas._libs.hashtable.PyObjectHashTable.get_item
  File "pandas/_libs/hashtable_class_helper.pxi", line 7088, in pandas._libs.hashtable.PyObjectHashTable.get_item
KeyError: 'isMobile'

The above exception was the direct cause of the following exception:

Traceback (most recent call last):
  File "/home/airflow/.local/lib/python3.8/site-packages/airflow/operators/python.py", line 192, in execute
    return_value = self.execute_callable()
  File "/home/airflow/.local/lib/python3.8/site-packages/airflow/operators/python.py", line 209, in execute_callable
    return self.python_callable(*self.op_args, **self.op_kwargs)
  File "/opt/airflow/dags/tugaskel8_dag.py", line 58, in load_data
    hook.run(f"INSERT INTO hands_on_final (id,city,name,entity,country,sources,'isMobile','isAnalysis',sensorType,firstUpdated,lastUpdated,measurements) VALUES ({row['id']}, '{row['city']}', '{row['name']}', '{row['entity']}', '{row['country']}', '{row['sources']}', {row['isMobile']}, {row['isAnalysis']}, '{row['sensorType']}', '{row['firstUpdated']}', '{row['lastUpdated']}', {row['measurements']})")
  File "/home/airflow/.local/lib/python3.8/site-packages/pandas/core/series.py", line 1007, in __getitem__
    return self._get_value(key)
  File "/home/airflow/.local/lib/python3.8/site-packages/pandas/core/series.py", line 1116, in _get_value
    loc = self.index.get_loc(label)
  File "/home/airflow/.local/lib/python3.8/site-packages/pandas/core/indexes/base.py", line 3655, in get_loc
    raise KeyError(key) from err
KeyError: 'isMobile'
[2023-10-26T05:34:16.538+0000] {taskinstance.py:1398} INFO - Marking task as FAILED. dag_id=etl_dag, task_id=load_data, execution_date=20231026T052400, start_date=20231026T053416, end_date=20231026T053416
[2023-10-26T05:34:16.560+0000] {standard_task_runner.py:104} ERROR - Failed to execute job 346 for task load_data ('isMobile'; 1368)
[2023-10-26T05:34:16.595+0000] {local_task_job_runner.py:228} INFO - Task exited with return code 1
[2023-10-26T05:34:16.617+0000] {taskinstance.py:2776} INFO - 0 downstream tasks scheduled from follow-on schedule check
