[2023-10-26T04:42:21.831+0000] {taskinstance.py:1157} INFO - Dependencies all met for dep_context=non-requeueable deps ti=<TaskInstance: etl_dag.load_data manual__2023-10-26T04:37:06.552293+00:00 [queued]>
[2023-10-26T04:42:21.851+0000] {taskinstance.py:1157} INFO - Dependencies all met for dep_context=requeueable deps ti=<TaskInstance: etl_dag.load_data manual__2023-10-26T04:37:06.552293+00:00 [queued]>
[2023-10-26T04:42:21.852+0000] {taskinstance.py:1359} INFO - Starting attempt 2 of 3
[2023-10-26T04:42:21.872+0000] {taskinstance.py:1380} INFO - Executing <Task(PythonOperator): load_data> on 2023-10-26 04:37:06.552293+00:00
[2023-10-26T04:42:21.882+0000] {standard_task_runner.py:57} INFO - Started process 1375 to run task
[2023-10-26T04:42:21.885+0000] {standard_task_runner.py:84} INFO - Running: ['***', 'tasks', 'run', 'etl_dag', 'load_data', 'manual__2023-10-26T04:37:06.552293+00:00', '--job-id', '222', '--raw', '--subdir', 'DAGS_FOLDER/tugaskel8_dag.py', '--cfg-path', '/tmp/tmp6vmduk8g']
[2023-10-26T04:42:21.889+0000] {standard_task_runner.py:85} INFO - Job 222: Subtask load_data
[2023-10-26T04:42:21.948+0000] {task_command.py:415} INFO - Running <TaskInstance: etl_dag.load_data manual__2023-10-26T04:37:06.552293+00:00 [running]> on host d73c1ff20372
[2023-10-26T04:42:22.317+0000] {taskinstance.py:1660} INFO - Exporting env vars: AIRFLOW_CTX_DAG_OWNER='kel8' AIRFLOW_CTX_DAG_ID='etl_dag' AIRFLOW_CTX_TASK_ID='load_data' AIRFLOW_CTX_EXECUTION_DATE='2023-10-26T04:37:06.552293+00:00' AIRFLOW_CTX_TRY_NUMBER='2' AIRFLOW_CTX_DAG_RUN_ID='manual__2023-10-26T04:37:06.552293+00:00'
[2023-10-26T04:42:22.581+0000] {taskinstance.py:1935} ERROR - Task failed with exception
Traceback (most recent call last):
  File "/home/airflow/.local/lib/python3.8/site-packages/airflow/operators/python.py", line 192, in execute
    return_value = self.execute_callable()
  File "/home/airflow/.local/lib/python3.8/site-packages/airflow/operators/python.py", line 209, in execute_callable
    return self.python_callable(*self.op_args, **self.op_kwargs)
  File "/opt/airflow/dags/tugaskel8_dag.py", line 45, in load_data
    final_df['coordinates'] = final_df['coordinates'].apply(lambda x: x.tolist())
  File "/home/airflow/.local/lib/python3.8/site-packages/pandas/core/series.py", line 4630, in apply
    return SeriesApply(self, func, convert_dtype, args, kwargs).apply()
  File "/home/airflow/.local/lib/python3.8/site-packages/pandas/core/apply.py", line 1025, in apply
    return self.apply_standard()
  File "/home/airflow/.local/lib/python3.8/site-packages/pandas/core/apply.py", line 1076, in apply_standard
    mapped = lib.map_infer(
  File "pandas/_libs/lib.pyx", line 2834, in pandas._libs.lib.map_infer
  File "/opt/airflow/dags/tugaskel8_dag.py", line 45, in <lambda>
    final_df['coordinates'] = final_df['coordinates'].apply(lambda x: x.tolist())
AttributeError: 'dict' object has no attribute 'tolist'
[2023-10-26T04:42:22.611+0000] {taskinstance.py:1398} INFO - Marking task as UP_FOR_RETRY. dag_id=etl_dag, task_id=load_data, execution_date=20231026T043706, start_date=20231026T044221, end_date=20231026T044222
[2023-10-26T04:42:22.637+0000] {standard_task_runner.py:104} ERROR - Failed to execute job 222 for task load_data ('dict' object has no attribute 'tolist'; 1375)
[2023-10-26T04:42:22.663+0000] {local_task_job_runner.py:228} INFO - Task exited with return code 1
[2023-10-26T04:42:22.686+0000] {taskinstance.py:2776} INFO - 0 downstream tasks scheduled from follow-on schedule check
